#VRML_SIM R2025a utf8

EXTERNPROTO "https://raw.githubusercontent.com/cyberbotics/webots/R2025a/projects/objects/backgrounds/protos/TexturedBackgroundLight.proto"
EXTERNPROTO "https://raw.githubusercontent.com/cyberbotics/webots/R2025a/projects/objects/floors/protos/RectangleArena.proto"

WorldInfo {
  basicTimeStep 8
  FPS 30
}
Viewpoint {
  orientation 0.2796074081647206 -0.29622858734532453 -0.9132734099593619 4.842830111315848
  position -0.11766956461986372 -0.47651561545899035 0.3293725891373506
}
TexturedBackgroundLight {
}
Solid {
  translation 0.0817777 0.0157152 0.143639
  rotation 0.33226017683499137 0.7220048332737686 0.60688730059122 0.8460407287594778
  children [
    Shape {
      appearance Appearance {
        material Material {
          emissiveColor 0.7 0.3 0
        }
      }
      geometry Sphere {
        radius 0.02
      }
    }
  ]
  name "Ball"
  boundingObject Sphere {
    radius 0.02
  }
  physics Physics {
    density -1
    mass 0.05
  }
}
RectangleArena {
  translation 0 0 -0.1
}
Background {
  skyColor [
    0.15 0.45 1
  ]
}
Robot {
  translation 1.0023777875596492e-05 0.09950193965655668 -0.0003265728094521906
  rotation 0.9997969731664402 0.02014972798162274 -3.0157769628834224e-05 0.004979963381616657
  children [
    Solid {
      translation 0 0 -4.708799966518464e-05
      children [
        HingeJoint {
          jointParameters HingeJointParameters {
            position -0.005980015665971894
            axis 0 1 0
            anchor 0 -0.05 0.08
            minStop -3
            maxStop 3
            suspensionAxis 0 1 0
          }
          device [
            PositionSensor {
              name "Motor_Sensor"
            }
            RotationalMotor {
              name "ServoMotor"
              acceleration 1
              controlPID 30 0 0
              maxVelocity 0.5
              minPosition -1.5737
              maxPosition 1.5737
              maxTorque 100
            }
          ]
          endPoint Solid {
            translation -0.019939842594946515 -0.10999999999999999 0.06988057920191286
            rotation 0 1 0 6.2772052915136065
            children [
              DistanceSensor {
                translation 0.155 0.03 0.025
                rotation 0 0 1 3.14159
                name "ToF Sensor"
                lookupTable [
                  0 0 0
                  0.25 1000 0
                ]
              }
              Solid {
                translation 0.0300028 -5.00858e-07 -1.13296e-06
                rotation 0.42308420973632715 0.9060714491684952 -0.005854952902486761 7.33682e-06
                children [
                  Shape {
                    appearance Appearance {
                      material Material {
                        emissiveColor 0.3 0.3 0.3
                      }
                    }
                    geometry Mesh {
                      url [
                        "../../End Cap w ToF.obj"
                      ]
                    }
                  }
                ]
                name "End Cap w/ ToF"
                boundingObject Mesh {
                  url [
                    "../../End Cap w ToF.obj"
                  ]
                }
                physics Physics {
                }
              }
              Solid {
                translation -0.19 -1.30638e-09 4.21255e-06
                rotation -0.26011095787700805 0.9655768436321718 0.0019101396906674006 1.14075e-05
                children [
                  Shape {
                    appearance Appearance {
                      material Material {
                        emissiveColor 0.3 0.3 0.3
                      }
                    }
                    geometry Mesh {
                      url [
                        "../../End Cap.obj"
                      ]
                    }
                  }
                ]
                name "End Cap"
                boundingObject Mesh {
                  url [
                    "../../End Cap.obj"
                  ]
                }
                physics Physics {
                }
              }
              Solid {
                translation 0.02 0.01 0.01
                rotation 0 1 0 1.570796326794897
                children [
                  Shape {
                    appearance Appearance {
                      material Material {
                        emissiveColor 0.3 0.3 0.3
                      }
                    }
                    geometry Cylinder {
                      height 0.28
                      radius 0.005
                    }
                  }
                ]
                name "Rod_1"
                boundingObject Cylinder {
                  height 0.28
                  radius 0.005
                }
                physics Physics {
                  density -1
                  mass 1.5
                }
              }
              Solid {
                translation 0.02 0.05 0.01
                rotation 0 1 0 1.570796326794897
                children [
                  Shape {
                    appearance Appearance {
                      material Material {
                        emissiveColor 0.3 0.3 0.3
                      }
                    }
                    geometry Cylinder {
                      height 0.28
                      radius 0.005
                    }
                  }
                ]
                name "Rod_2"
                boundingObject Cylinder {
                  height 0.28
                  radius 0.005
                }
                physics Physics {
                  density -1
                  mass 1.5
                }
              }
              DEF Motor_Hinge_Shape Shape {
                appearance Appearance {
                  material Material {
                    emissiveColor 0.3 0.3 0.3
                  }
                }
                geometry Mesh {
                  url [
                    "../../Motor Stand.obj"
                  ]
                }
              }
            ]
            name "Motor_Stand_Hinge"
            boundingObject USE Motor_Hinge_Shape
            physics Physics {
            }
          }
        }
        DEF Tower_shape Shape {
          appearance Appearance {
            material Material {
              emissiveColor 0.1 0.1 0.1
            }
          }
          geometry Box {
            size 0.1 0.1 0.2
          }
        }
      ]
      name "Tower_Solid"
      boundingObject USE Tower_shape
      physics Physics {
      }
    }
  ]
  boundingObject USE Tower_shape
  physics Physics {
  }
  controller "self_ballz"
}
